Workbook

Sheet 0_OmogeneitàMagnete
B2: Direzione | C2: scostamento [mm] | D2: i [A] | E2: err i (oscill) | F2: B (i) [mT] | G2: err B (oscill)
B4: asse centrale | C4: 1 | D4: 2.5 | E4: 0.01 | F4: 173.4 | G4: 1 | H4: <-- | I4: errori usati inizialmente in lab.
B6: Piano perpendicolare
B7: orizzontale dx | D7: 2.51 | E7: =D7*0.03 + 0.1 -> 0.1753 | F7: 174 | G7: =F7*0.05 + 1 -> 9.7 | H7: <--
B8: orizzontale sx | D8: 2.5 | E8: =D8*0.03 + 0.1 -> 0.175 | F8: 173 | G8: =F8*0.05 + 1 -> 9.65 | I8: errore amperometro
B9: verticale up | D9: 2.51 | E9: =D9*0.03 + 0.1 -> 0.1753 | F9: 174.5 | G9: =F9*0.05 + 1 -> 9.725 | I9: 3% + 10cf
B10: verticale down | D10: 2.51 | E10: =D10*0.03 + 0.1 -> 0.1753 | F10: 174.2 | G10: =F10*0.05 + 1 -> 9.71
I11: errore teslametro
B12: Piano parallelo | I12: 5% + 10cf
B13: avanti | D13: 2.5 | E13: =D13*0.03 + 0.1 -> 0.175 | F13: 173.4 | G13: =F13*0.05 + 1 -> 9.67
B14: indietro | D14: 2.49 | E14: =D14*0.03 + 0.1 -> 0.1747 | F14: 173.4 | G14: =F14*0.05 + 1 -> 9.67
F17: piu o meno
D18: B massimo | E18: =MAX(F4:F14) -> 174.5 | F18: =E18*0.05 + 1 -> 9.725 | H18: Semidispesione massima su B
D19: B centrale | E19: =F4 -> 173.4 | F19: =E19*0.05 + 1 -> 9.67 | H19: =(max(F7:F14)-MIN(F7:F14))/2 -> 0.75
D21: errore posiz | E21: =E18-E19 -> 1.1

Sheet 1_TaraturaMagnete
B3: Rampa 1 - salita | G3: Rampa 2 - discesa | L3: Rampa 3 - salita | Q3: Rampa 4 - discesa
B4: i_1 | C4: ei_1 | D4: B_1 | E4: eB_1 | G4: i_2 | H4: ei_2 | I4: B_2 | J4: eB_2 | L4: i_3 | M4: ei_3 | N4: B_3 | O4: eB_3 | Q4: i_4 | R4: ei_4 | S4: B_4 | T4: eB_4
B5: 0 | C5: =B5*0.03 + 0.1 -> 0.1 | D5: 9.1 | E5: =D5*0.05 + 0.1 -> 0.555 | G5: 10.01 | H5: =G5*0.03 + 0.1 -> 0.4003 | I5: 625 | J5: =I5*0.05 + 1 -> 32.25 | L5: 0 | M5: =L5*0.03 + 0.1 -> 0.1 | N5: 9.97 | O5: =N5*0.05 + 0.1 -> 0.5985 | Q5: 9.99 | R5: =Q5*0.03 + 0.1 -> 0.3997 | S5: 626.4 | T5: =S5*0.05 + 1 -> 32.32
B6: 1.04 | C6: =B6*0.03 + 0.1 -> 0.1312 | D6: 74.96 | E6: =D6*0.05 + 0.1 -> 3.848 | G6: 9.06 | H6: =G6*0.03 + 0.1 -> 0.3718 | I6: 586.3 | J6: =I6*0.05 + 1 -> 30.315 | L6: 1.05 | M6: =L6*0.03 + 0.1 -> 0.1315 | N6: 78.43 | O6: =N6*0.05 + 0.1 -> 4.0215 | Q6: 9.01 | R6: =Q6*0.03 + 0.1 -> 0.3703 | S6: 585.1 | T6: =S6*0.05 + 1 -> 30.255
B7: 2.04 | C7: =B7*0.03 + 0.1 -> 0.1612 | D7: 141.09 | E7: =D7*0.05 + 0.1 -> 7.1545 | G7: 8.04 | H7: =G7*0.03 + 0.1 -> 0.3412 | I7: 534.2 | J7: =I7*0.05 + 1 -> 27.71 | L7: 2.02 | M7: =L7*0.03 + 0.1 -> 0.1606 | N7: 144.87 | O7: =N7*0.05 + 0.1 -> 7.3435 | Q7: 8 | R7: =Q7*0.03 + 0.1 -> 0.34 | S7: 530 | T7: =S7*0.05 + 1 -> 27.5
B8: 3.1 | C8: =B8*0.03 + 0.1 -> 0.193 | D8: 209.51 | E8: =D8*0.05 + 0.1 -> 10.5755 | G8: 7.12 | H8: =G8*0.03 + 0.1 -> 0.3136 | I8: 478.4 | J8: =I8*0.05 + 1 -> 24.92 | L8: 2.98 | M8: =L8*0.03 + 0.1 -> 0.1894 | N8: 206.38 | O8: =N8*0.05 + 0.1 -> 10.419 | Q8: 7.06 | R8: =Q8*0.03 + 0.1 -> 0.3118 | S8: 475.5 | T8: =S8*0.05 + 1 -> 24.775
B9: 4 | C9: =B9*0.03 + 0.1 -> 0.22 | D9: 273.14 | E9: =D9*0.05 + 1 -> 14.657 | G9: 6.03 | H9: =G9*0.03 + 0.1 -> 0.2809 | I9: 412 | J9: =I9*0.05 + 1 -> 21.6 | L9: 3.96 | M9: =L9*0.03 + 0.1 -> 0.2188 | N9: 271.76 | O9: =N9*0.05 + 0.1 -> 13.688 | Q9: 6 | R9: =Q9*0.03 + 0.1 -> 0.28 | S9: 410.5 | T9: =S9*0.05 + 1 -> 21.525
B10: 4.97 | C10: =B10*0.03 + 0.1 -> 0.2491 | D10: 336.5 | E10: =D10*0.05 + 1 -> 17.825 | G10: 5.02 | H10: =G10*0.03 + 0.1 -> 0.2506 | I10: 346.6 | J10: =I10*0.05 + 1 -> 18.33 | L10: 4.98 | M10: =L10*0.03 + 0.1 -> 0.2494 | N10: 339.5 | O10: =N10*0.05 + 1 -> 17.975 | Q10: 5 | R10: =Q10*0.03 + 0.1 -> 0.25 | S10: 347 | T10: =S10*0.05 + 1 -> 18.35
B11: 5.94 | C11: =B11*0.03 + 0.1 -> 0.2782 | D11: 408.6 | E11: =D11*0.05 + 1 -> 21.43 | G11: 3.99 | H11: =G11*0.03 + 0.1 -> 0.2197 | I11: 275.9 | J11: =I11*0.05 + 1 -> 14.795 | L11: 6.01 | M11: =L11*0.03 + 0.1 -> 0.2803 | N11: 407.2 | O11: =N11*0.05 + 1 -> 21.36 | Q11: 3.9 | R11: =Q11*0.03 + 0.1 -> 0.217 | S11: 272.61 | T11: =S11*0.05 + 0.1 -> 13.7305
B12: 6.97 | C12: =B12*0.03 + 0.1 -> 0.3091 | D12: 465.1 | E12: =D12*0.05 + 1 -> 24.255 | G12: 3.02 | H12: =G12*0.03 + 0.1 -> 0.1906 | I12: 215.4 | J12: =I12*0.05 + 0.1 -> 10.87 | L12: 7.02 | M12: =L12*0.03 + 0.1 -> 0.3106 | N12: 471.4 | O12: =N12*0.05 + 1 -> 24.57 | Q12: 3 | R12: =Q12*0.03 + 0.1 -> 0.19 | S12: 214.43 | T12: =S12*0.05 + 0.1 -> 10.8215
B13: 8 | C13: =B13*0.03 + 0.1 -> 0.34 | D13: 527.9 | E13: =D13*0.05 + 1 -> 27.395 | G13: 2.16 | H13: =G13*0.03 + 0.1 -> 0.1648 | I13: 153.08 | J13: =I13*0.05 + 0.1 -> 7.754 | L13: 8.06 | M13: =L13*0.03 + 0.1 -> 0.3418 | N13: 535.7 | O13: =N13*0.05 + 1 -> 27.785 | Q13: 2.04 | R13: =Q13*0.03 + 0.1 -> 0.1612 | S13: 150.33 | T13: =S13*0.05 + 0.1 -> 7.6165
B14: 8.98 | C14: =B14*0.03 + 0.1 -> 0.3694 | D14: 581.3 | E14: =D14*0.05 + 1 -> 30.065 | G14: 1.12 | H14: =G14*0.03 + 0.1 -> 0.1336 | I14: 87.28 | J14: =I14*0.05 + 0.1 -> 4.464 | L14: 9.06 | M14: =L14*0.03 + 0.1 -> 0.3718 | N14: 582.7 | O14: =N14*0.05 + 1 -> 30.135 | Q14: 0.98 | R14: =Q14*0.03 + 0.1 -> 0.1294 | S14: 79.31 | T14: =S14*0.05 + 0.1 -> 4.0655
B15: 10.01 | C15: =B15*0.03 + 0.1 -> 0.4003 | D15: 625 | E15: =D15*0.05 + 1 -> 32.25 | G15: 0 | H15: =G15*0.03 + 0.1 -> 0.1 | I15: 9.98 | J15: =I15*0.05 + 0.1 -> 0.599 | L15: 9.99 | M15: =L15*0.03 + 0.1 -> 0.3997 | N15: 626.4 | O15: =N15*0.05 + 1 -> 32.32 | Q15: 0 | R15: =Q15*0.03 + 0.1 -> 0.1 | S15: 9.78 | T15: =S15*0.05 + 0.1 -> 0.589
B33: Dopo il fit
B35: rampa | C35: m | D35: err m | E35: pesi | F35: q | G35: err q | H35: pesi | I35: chi2
B36: 1 | C36: 65.35 | D36: 2.1 | E36: =1/(D36)^2 -> 0.22675737 | F36: 8.56 | G36: 5.43 | H36: =1/(G36)^2 -> 0.033915665 | I36: -
B37: 2 | C37: 65.74 | D37: 2.09 | E37: =1/(D37)^2 -> 0.22893249 | F37: 11.58 | G37: 5.51 | H37: =1/(G37)^2 -> 0.032937968 | I37: -
B38: 3 | C38: 64.71 | D38: 1.91 | E38: =1/(D38)^2 -> 0.27411529 | F38: 11.22 | G38: 5.31 | H38: =1/(G38)^2 -> 0.035465898 | I38: -
B39: 4 | C39: 65.19 | D39: 1.91 | E39: =1/(D39)^2 -> 0.27411529 | F39: 13.02 | G39: 5.32 | H39: =1/(G39)^2 -> 0.035332693 | I39: -
B40: media pesata | C40: =(C36*E36+C37*E37+C38*E38+C39*E39)/(E36+E37+E38+E39) -> 65.220499 | D40: =SQRT(1/(E36+E37+E38+E39)) -> 0.99804552 | F40: =(F36*H36+F37*H37+F38*H38+F39*H39)/(H36+H37+H38+H39) -> 11.112779 | G40: =SQRT(1/(H36+H37+H38+H39)) -> 2.6953079 | I40: -
B41: media | C41: =AVERAGE(C36:C39) -> 65.2475 | D41: =AVERAGE(D36:D39) -> 2.0025 | F41: =AVERAGE(F36:F39) -> 11.095 | G41: =AVERAGE(G36:G39) -> 5.3925 | I41: -
B45: q | C45: Z_12 | D45: Z_13 | E45: Z_14 | F45: Z_23 | G45: Z_24 | H45: Z_34
C46: =ABS(C36-C37)/SQRT((D36)^2+(D37)^2) -> 0.13163287 | D46: =ABS(C36-C38)/SQRT((D36)^2+(D38)^2) -> 0.22545696 | E46: =ABS(C36-C39)/SQRT((D36)^2+(D39)^2) -> 0.05636424 | F46: =ABS(C37-C38)/SQRT((D37)^2+(D38)^2) -> 0.36379184 | G46: =ABS(C37-C39)/SQRT((D37)^2+(D39)^2) -> 0.19425778 | H46: =ABS(C38-C39)/SQRT((D38)^2+(D39)^2) -> 0.17770223
B48: m | C48: Z_12 | D48: Z_13 | E48: Z_14 | F48: Z_23 | G48: Z_24 | H48: Z_34
C49: =ABS(F36-F37)/SQRT((G36)^2+(G37)^2) -> 0.3903849 | D49: =ABS(F36-F38)/SQRT((G36)^2+(G38)^2) -> 0.3502396 | E49: =ABS(F36-F39)/SQRT((G36)^2+(G39)^2) -> 0.58670347 | F49: =ABS(F37-F38)/SQRT((G37)^2+(G38)^2) -> 0.04704528 | G49: =ABS(F37-F39)/SQRT((G37)^2+(G39)^2) -> 0.18801055 | H49: =ABS(F38-F39)/SQRT((G38)^2+(G39)^2) -> 0.23947162

Sheet 2_ZeemanTrasversale
B2: i [A] | C2: ei [A] | D2: B [mT] | E2: eB [mT] | F2: B [T] | G2: eB [T] | H2: N° Ordine | I2: A_a | J2: A_b | K2: A_c | L2: δ_ab | M2: δ_bc | N2: <δ_ab> | O2: e<δ_ab> | P2: <δ_bc> | Q2: e<δ_bc> | R2: sopra Δ_12 sotto Δ_23 | U2: <Δ_12> | V2: e<Δ_12> | W2: <Δ_23> | X2: e<Δ_23> | Y2: <δ_ab>/<Δ_12> | Z2: e<δ_ab>/<Δ_12> | AA2: <δ_ab>/<Δ_23> | AB2: e<δ_ab>/<Δ_23> | AC2: <δ_bc>/<Δ_12> | AD2: e<δ_bc>/<Δ_12> | AE2: <δ_bc>/<Δ_23> | AF2: e<δ_bc>/<Δ_23>
B3: 0 | C3: =B3*0.03 + 0.1 -> 0.1 | D3: =11.11 + 65.22*B3 -> 11.11 | E3: =SQRT(B3^2*'1_TaraturaMagnete'!$D$40^2 + '1_TaraturaMagnete'!$C$40^2*C3^2 +'1_TaraturaMagnete'!$G$40^2 ) -> 7.0570404 | F3: =D3/1000 -> 0.01111 | G3: =E3/1000 -> 0.0070570404 | H3: 1° | I3: - | J3: - | K3: - | L3: - | M3: - | N3: - | P3: - | R3: - | S3: - | T3: - | U3: - | W3: - | Y3: - | AA3: - | AC3: - | AE3: -
H4: 2° | I4: - | J4: - | K4: - | L4: - | M4: - | N4: - | P4: - | R4: - | S4: - | T4: - | U4: - | W4: - | Y4: - | AA4: - | AC4: - | AE4: -
H5: 3° | I5: - | J5: - | K5: - | L5: - | M5: - | N5: - | P5: - | R5: - | S5: - | T5: - | U5: - | W5: - | Y5: - | AA5: - | AC5: - | AE5: -
B6: 4.9 | C6: =B6*0.03 + 0.1 -> 0.247 | D6: =11.11 + 65.22*B6 -> 330.688 | E6: =SQRT(B6^2*'1_TaraturaMagnete'!$D$40^2 + '1_TaraturaMagnete'!$C$40^2*C6^2 +'1_TaraturaMagnete'!$G$40^2 ) -> 17.049801 | F6: =D6/1000 -> 0.330688 | G6: =E6/1000 -> 0.017049801 | H6: 1° | I6: 104039.49 | J6: 120873.95 | K6: 138758.31 | L6: =I6-J6 -> -16834.453 | M6: =J6-K6 -> -17884.367 | N6: =AVERAGE(L6:L8) -> -17812.88 | O6: =(MAX(L6:L8)-MIN(L6:L8))/2 -> 4062.8125 | P6: =AVERAGE(M6:M8) -> -18468.247 | Q6: =(MAX(M6:M8)-MIN(M6:M8))/2 -> 2423.75 | R6: =I6-I7 -> -132402.26 | S6: =J6-J7 -> -129807.09 | T6: =K6-K7 -> -133106.66 | U6: =AVERAGE(R6:T6) -> -131772 | V6: =(MAX(R6:T6)-MIN(R6:T6))/2 -> 1649.7852 | W6: =AVERAGE(R7:T7) -> -129885.81 | X6: =(MAX(R7:T7)-MIN(R7:T7))/2 -> 4062.8125 | Y6: =N6/U6 -> 0.13517955 | Z6: =SQRT((1/U6)^2*(O6)^2 + (N6/(U6)^2)^2*(V6)^2) -> 0.030878554 | AA6: =N6/W6 -> 0.13714262 | AB6: =SQRT((1/W6)^2*(O6)^2 + (O6/(W6)^2)^2*(X6)^2) -> 0.031295178 | AC6: =P6/U6 -> 0.14015305 | AD6: =SQRT((1/U6)^2*(Q6)^2 + (P6/(U6)^2)^2*(V6)^2) -> 0.018477022 | AE6: =P6/W6 -> 0.14218833 | AF6: =SQRT((1/W6)^2*(Q6)^2 + (P6/(W6)^2)^2*(X6)^2) -> 0.019183333
H7: 2° | I7: 236441.75 | J7: 250681.03 | K7: 271864.97 | L7: =I7-J7 -> -14239.281 | M7: =J7-K7 -> -21183.938 | R7: =I7-I8 -> -126084.56 | S7: =J7-J8 -> -134210.19 | T7: =K7-K8 -> -129362.69
H8: 3° | I8: 362526.31 | J8: 384891.22 | K8: 401227.66 | L8: =I8-J8 -> -22364.906 | M8: =J8-K8 -> -16336.438
B9: 6 | C9: =B9*0.03 + 0.1 -> 0.28 | D9: =11.11 + 65.22*B9 -> 402.43 | E9: =SQRT(B9^2*'1_TaraturaMagnete'!$D$40^2 + '1_TaraturaMagnete'!$C$40^2*C9^2 +'1_TaraturaMagnete'!$G$40^2 ) -> 19.406577 | F9: =D9/1000 -> 0.40243 | G9: =E9/1000 -> 0.019406577 | H9: 1° | I9: 106434.58 | J9: 126046.28 | K9: 145700.61 | L9: =I9-J9 -> -19611.703 | M9: =J9-K9 -> -19654.328 | N9: =AVERAGE(L9:L11) -> -16053.599 | O9: =(MAX(L9:L11)-MIN(L9:L11))/2 -> 4013.4141 | P9: =AVERAGE(M9:M11) -> -21573.844 | Q9: =(MAX(M9:M11)-MIN(M9:M11))/2 -> 2456.1406 | R9: =I9-I10 -> -126933.59 | S9: =J9-J10 -> -124286.11 | T9: =K9-K10 -> -129198.39 | U9: =AVERAGE(R9:T9) -> -126806.03 | V9: =(MAX(R9:T9)-MIN(R9:T9))/2 -> 2456.1406 | W9: =AVERAGE(R10:T10) -> -128433.64 | X9: =(MAX(R10:T10)-MIN(R10:T10))/2 -> 4722.6797 | Y9: =N9/U9 -> 0.12659965 | Z9: =SQRT((1/U9)^2*(O9)^2 + (N9/(U9)^2)^2*(V9)^2) -> 0.031744875 | AA9: =N9/W9 -> 0.12499529 | AB9: =SQRT((1/W9)^2*(O9)^2 + (O9/(W9)^2)^2*(X9)^2) -> 0.031270052 | AC9: =P9/U9 -> 0.17013263 | AD9: =SQRT((1/U9)^2*(Q9)^2 + (P9/(U9)^2)^2*(V9)^2) -> 0.019647596 | AE9: =P9/W9 -> 0.16797659 | AF9: =SQRT((1/W9)^2*(Q9)^2 + (P9/(W9)^2)^2*(X9)^2) -> 0.02009657
H10: 2° | I10: 233368.17 | J10: 250332.39 | K10: 274899 | L10: =I10-J10 -> -16964.219 | M10: =J10-K10 -> -24566.609 | R10: =I10-I11 -> -133375.2 | S10: =J10-J11 -> -127995.86 | T10: =K10-K11 -> -123929.84
H11: 3° | I11: 366743.38 | J11: 378328.25 | K11: 398828.84 | L11: =I11-J11 -> -11584.875 | M11: =J11-K11 -> -20500.594
B12: 7.11 | C12: =B12*0.03 + 0.1 -> 0.3133 | D12: =11.11 + 65.22*B12 -> 474.8242 | E12: =SQRT(B12^2*'1_TaraturaMagnete'!$D$40^2 + '1_TaraturaMagnete'!$C$40^2*C12^2 +'1_TaraturaMagnete'!$G$40^2 ) -> 21.797951 | F12: =D12/1000 -> 0.4748242 | G12: =E12/1000 -> 0.021797951 | H12: 1° | I12: 101984.34 | J12: 124241.94 | K12: 151196.45 | L12: =I12-J12 -> -22257.594 | M12: =J12-K12 -> -26954.516 | N12: =AVERAGE(L12:L14) -> -23109.927 | O12: =(MAX(L12:L14)-MIN(L12:L14))/2 -> 1062.6562 | P12: =AVERAGE(M12:M14) -> -24307.021 | Q12: =(MAX(M12:M14)-MIN(M12:M14))/2 -> 2404.1172 | R12: =I12-I13 -> -126626.67 | S12: =J12-J13 -> -128751.98 | T12: =K12-K13 -> -125617.73 | U12: =AVERAGE(R12:T12) -> -126998.8 | V12: =(MAX(R12:T12)-MIN(R12:T12))/2 -> 1567.125 | W12: =AVERAGE(R13:T13) -> -128491.16 | X12: =(MAX(R13:T13)-MIN(R13:T13))/2 -> 1683.8047 | Y12: =N12/U12 -> 0.18196965 | Z12: =SQRT((1/U12)^2*(O12)^2 + (N12/(U12)^2)^2*(V12)^2) -> 0.0086635027 | AA12: =N12/W12 -> 0.17985617 | AB12: =SQRT((1/W12)^2*(O12)^2 + (O12/(W12)^2)^2*(X12)^2) -> 0.0082709777 | AC12: =P12/U12 -> 0.19139568 | AD12: =SQRT((1/U12)^2*(Q12)^2 + (P12/(U12)^2)^2*(V12)^2) -> 0.019076995 | AE12: =P12/W12 -> 0.18917271 | AF12: =SQRT((1/W12)^2*(Q12)^2 + (P12/(W12)^2)^2*(X12)^2) -> 0.018873882
H13: 2° | I13: 228611.02 | J13: 252993.92 | K13: 276814.19 | L13: =I13-J13 -> -24382.906 | M13: =J13-K13 -> -23820.266 | R13: =I13-I14 -> -130178.23 | S13: =J13-J14 -> -128484.61 | T13: =K13-K14 -> -126810.62
H14: 3° | I14: 358789.25 | J14: 381478.53 | K14: 403624.81 | L14: =I14-J14 -> -22689.281 | M14: =J14-K14 -> -22146.281
B15: 8 | C15: =B15*0.03 + 0.1 -> 0.34 | D15: =11.11 + 65.22*B15 -> 532.87 | E15: =SQRT(B15^2*'1_TaraturaMagnete'!$D$40^2 + '1_TaraturaMagnete'!$C$40^2*C15^2 +'1_TaraturaMagnete'!$G$40^2 ) -> 23.722227 | F15: =D15/1000 -> 0.53287 | G15: =E15/1000 -> 0.023722227 | H15: 1° | I15: 98802.477 | J15: 125348.04 | K15: 154441.34 | L15: =I15-J15 -> -26545.562 | M15: =J15-K15 -> -29093.305 | N15: =AVERAGE(L15:L17) -> -27821.948 | O15: =(MAX(L15:L17)-MIN(L15:L17))/2 -> 2763.0156 | P15: =AVERAGE(M15:M17) -> -27194.211 | Q15: =(MAX(M15:M17)-MIN(M15:M17))/2 -> 1577.8789 | R15: =I15-I16 -> -128218.79 | S15: =J15-J16 -> -127370.35 | T15: =K15-K16 -> -124214.59 | U15: =AVERAGE(R15:T15) -> -126601.24 | V15: =(MAX(R15:T15)-MIN(R15:T15))/2 -> 2002.0977 | W15: =AVERAGE(R16:T16) -> -128438.5 | X15: =(MAX(R16:T16)-MIN(R16:T16))/2 -> 3070.1328 | Y15: =N15/U15 -> 0.21976046 | Z15: =SQRT((1/U15)^2*(O15)^2 + (N15/(U15)^2)^2*(V15)^2) -> 0.022099527 | AA15: =N15/W15 -> 0.21661689 | AB15: =SQRT((1/W15)^2*(O15)^2 + (O15/(W15)^2)^2*(X15)^2) -> 0.021518508 | AC15: =P15/U15 -> 0.21480208 | AD15: =SQRT((1/U15)^2*(Q15)^2 + (P15/(U15)^2)^2*(V15)^2) -> 0.012918004 | AE15: =P15/W15 -> 0.21172943 | AF15: =SQRT((1/W15)^2*(Q15)^2 + (P15/(W15)^2)^2*(X15)^2) -> 0.013286762
H16: 2° | I16: 227021.27 | J16: 252718.39 | K16: 278655.94 | L16: =I16-J16 -> -25697.125 | M16: =J16-K16 -> -25937.547 | R16: =I16-I17 -> -124549.73 | S16: =J16-J17 -> -130075.77 | T16: =K16-K17 -> -130690
H17: 3° | I17: 351571 | J17: 382794.16 | K17: 409345.94 | L17: =I17-J17 -> -31223.156 | M17: =J17-K17 -> -26551.781
B18: 9.1 | C18: =B18*0.03 + 0.1 -> 0.373 | D18: =11.11 + 65.22*B18 -> 604.612 | E18: =SQRT(B18^2*'1_TaraturaMagnete'!$D$40^2 + '1_TaraturaMagnete'!$C$40^2*C18^2 +'1_TaraturaMagnete'!$G$40^2 ) -> 26.106823 | F18: =D18/1000 -> 0.604612 | G18: =E18/1000 -> 0.026106823 | H18: 1° | I18: 95394.758 | J18: 123077.76 | K18: 154979.75 | L18: =I18-J18 -> -27683 | M18: =J18-K18 -> -31901.992 | N18: =AVERAGE(L18:L20) -> -29169.682 | O18: =(MAX(L18:L20)-MIN(L18:L20))/2 -> 2722.6172 | P18: =AVERAGE(M18:M20) -> -31198.596 | Q18: =(MAX(M18:M20)-MIN(M18:M20))/2 -> 3920.7578 | R18: =I18-I19 -> -125415.24 | S18: =J18-J19 -> -130367.88 | T18: =K18-K19 -> -125392.03 | U18: =AVERAGE(R18:T18) -> -127058.39 | V18: =(MAX(R18:T18)-MIN(R18:T18))/2 -> 2487.9258 | W18: =AVERAGE(R19:T19) -> -126860.37 | X18: =(MAX(R19:T19)-MIN(R19:T19))/2 -> 3920.7578 | Y18: =N18/U18 -> 0.22957699 | Z18: =SQRT((1/U18)^2*(O18)^2 + (N18/(U18)^2)^2*(V18)^2) -> 0.021894535 | AA18: =N18/W18 -> 0.22993534 | AB18: =SQRT((1/W18)^2*(O18)^2 + (O18/(W18)^2)^2*(X18)^2) -> 0.021471774 | AC18: =P18/U18 -> 0.24554535 | AD18: =SQRT((1/U18)^2*(Q18)^2 + (P18/(U18)^2)^2*(V18)^2) -> 0.031230248 | AE18: =P18/W18 -> 0.24592863 | AF18: =SQRT((1/W18)^2*(Q18)^2 + (P18/(W18)^2)^2*(X18)^2) -> 0.031826983
H19: 2° | I19: 220810 | J19: 253445.64 | K19: 280371.78 | L19: =I19-J19 -> -32635.641 | M19: =J19-K19 -> -26926.141 | R19: =I19-I20 -> -127876.69 | S19: =J19-J20 -> -122431.45 | T19: =K19-K20 -> -130272.97
H20: 3° | I20: 348686.69 | J20: 375877.09 | K20: 410644.75 | L20: =I20-J20 -> -27190.406 | M20: =J20-K20 -> -34767.656
B26: Dati per analsi dati
B27: B | C27: eB | D27: dDab12 | E27: edDab12 | F27: dDab23 | G27: edDab23 | H27: dDbc12 | I27: edDbc12 | J27: dDbc23 | K27: edDbc23
B28: 0.01111 | C28: 0.0070570404 | D28: 0 | E28: 0 | F28: 0 | G28: 0 | H28: 0 | I28: 0 | J28: 0 | K28: 0
B29: 0.330688 | C29: 0.017049801 | D29: 0.13517955 | E29: 0.030878554 | F29: 0.13714262 | G29: 0.031295178 | H29: 0.14015305 | I29: 0.018477022 | J29: 0.14218833 | K29: 0.019183333 | M29: Magnetone di Bohr (teorico)
B30: 0.40243 | C30: 0.019406577 | D30: 0.12659965 | E30: 0.031744875 | F30: 0.12499529 | G30: 0.031270052 | H30: 0.17013263 | I30: 0.019647596 | J30: 0.16797659 | K30: 0.02009657 | M30: 9.2740095e-24
B31: 0.4748242 | C31: 0.021797951 | D31: 0.18196965 | E31: 0.0086635027 | F31: 0.17985617 | G31: 0.0082709777 | H31: 0.19139568 | I31: 0.019076995 | J31: 0.18917271 | K31: 0.018873882
B32: 0.53287 | C32: 0.023722227 | D32: 0.21976046 | E32: 0.022099527 | F32: 0.21661689 | G32: 0.021518508 | H32: 0.21480208 | I32: 0.012918004 | J32: 0.21172943 | K32: 0.013286762
B33: 0.604612 | C33: 0.026106823 | D33: 0.22957699 | E33: 0.021894535 | F33: 0.22993534 | G33: 0.021471774 | H33: 0.24554536 | I33: 0.031230248 | J33: 0.24592863 | K33: 0.031826983
B37: Fit dDab12 | G37: Fit dDab23 | L37: Fit dDbc12 | Q37: Fit dDbc23
B38: p0 | C38: e_p0 | D38: p1 | E38: e_p1 | G38: p0 | H38: e_p0 | I38: p1 | J38: e_p1 | L38: p0 | M38: e_p0 | N38: p1 | O38: e_p1 | Q38: p0 | R38: e_p0 | S38: p1 | T38: e_p1
B39: -0.004 | C39: 0.003 | D39: 0.394 | E39: 0.02 | G39: -0.004 | H39: 0.003 | I39: 0.391 | J39: 0.019 | L39: -0.005 | M39: 0.003 | N39: 0.418 | O39: 0.021 | Q39: -0.005 | R39: 0.003 | S39: 0.415 | T39: 0.022
C41: μ_b | D41: e μ_b | H41: μ_b | I41: e μ_b | M41: μ_b | N41: e μ_b | R41: μ_b | S41: e μ_b
C42: =(D39*6.626*10^(-34)*2.998*10^8)/(2*3*10^(-3)*1.456*1) -> 0 | D42: =SQRT(((6.626*10^(-34)*2.998*10^8)/(2*3*10^(-3)*1.456*1))^2*(E39)^2) -> 0 | E42: =1/(D42)^2 -> 4.83503e+48 | H42: =(I39*6.626*10^(-34)*2.998*10^8)/(2*3*10^(-3)*1.456*1) -> 0 | I42: =SQRT(((6.626*10^(-34)*2.998*10^8)/(2*3*10^(-3)*1.456*1))^2*(J39)^2) -> 0 | J42: =1/(I42)^2 -> 5.35737e+48 | M42: =(N39*6.626*10^(-34)*2.998*10^8)/(2*3*10^(-3)*1.456*1) -> 0 | N42: =SQRT(((6.626*10^(-34)*2.998*10^8)/(2*3*10^(-3)*1.456*1))^2*(O39)^2) -> 0 | O42: =1/(N42)^2 -> 4.38551e+48 | R42: =(S39*6.626*10^(-34)*2.998*10^8)/(2*3*10^(-3)*1.456*1) -> 0 | S42: =SQRT(((6.626*10^(-34)*2.998*10^8)/(2*3*10^(-3)*1.456*1))^2*(T39)^2) -> 0 | T42: =1/(S42)^2 -> 3.99589e+48
C44: Test Z - dDab12 | H44: Test Z - dDab23 | M44: Test Z - dDbc12 | R44: Test Z - dDbc23
C45: Z_value | D45: =ABS(C42-$M$30)/D42 -> 0.69234198 | H45: Z_value | I45: =ABS(H42-$M$30)/I42 -> 0.88667577 | M45: Z_value | N45: =ABS(M42-$M$30)/N42 -> 0.48348383 | R45: Z_value | S45: =ABS(R42-$M$30)/S42 -> 0.32514366
C47: =(C42*E42+H42*J42+M42*O42+R42*T42)/(E42+J42+O42+T42) -> 0 | D47: =SQRT(1/(E42+J42+O42+T42)) -> 0

Sheet 3_ZeemanLongitudinale
B2: i [A] | C2: ei [A] | D2: B [mT] | E2: eB [mT] | F2: B [T] | G2: eB [T] | H2: A_a | I2: A_b | J2: δ | K2: <δ> | L2: e<δ> | M2: Δ_aa | N2: Δ_bb | O2: <Δ> | P2: e<Δ> | Q2: <δ>/<Δ> | R2: e< δ/Δ > | T2: i [A] | U2: ei [A] | V2: B [mT] | W2: eB [mT] | X2: B [T] | Y2: eB [T] | Z2: r_a | AA2: r_b | AB2: r_a^2 | AC2: r_b^2 | AD2: δ | AE2: <δ> | AF2: e<δ> | AG2: Δ_aa | AH2: Δ_bb | AI2: <Δ> | AJ2: e<Δ> | AK2: <δ>/<Δ> | AL2: e< δ/Δ >
B3: 2.16 | C3: =B3*0.03 + 0.1 -> 0.1648 | D3: =11.11 + 65.22*B3 -> 151.9852 | E3: =SQRT(B3^2*'1_TaraturaMagnete'!$D$40^2 + '1_TaraturaMagnete'!$C$40^2*C3^2 +'1_TaraturaMagnete'!$G$40^2 ) -> 11.288881 | F3: =D3/1000 -> 0.1519852 | G3: =E3/1000 -> 0.011288881 | H3: 118492.13 | I3: 133386.48 | J3: =H3-I3 -> -14894.352 | K3: =AVERAGE(J3:J5) -> -15931.232 | L3: =(MAX(J3:J5) - MIN(J3:J5))/2 -> 1000.793 | M3: =H4-H3 -> 124272.43 | N3: =I4-I3 -> 125381.48 | O3: =AVERAGE(M3:N4) -> 125475.77 | P3: =(MAX(M3:N4)-MIN(M3:N4))/2 -> 1149.207 | Q3: =K3/O3 -> -0.1269666 | R3: =SQRT((1/O3)^2*(L3)^2 + (K3/(O3)^2)^2*(P3)^2) -> 0.0080603101 | T3: =B3 -> 2.16 | U3: =C3 -> 0.1648 | V3: =D3 -> 151.9852 | W3: =E3 -> 11.288881 | X3: =V3/1000 -> 0.1519852 | Y3: =W3/1000 -> 0.011288881 | Z3: 194.20921 | AA3: 206.05397 | AB3: =Z3^2 -> 37717.218 | AC3: =AA3^2 -> 42458.239 | AD3: =AB3-AC3 -> -4741.0201 | AE3: =AVERAGE(AD3:AD5) -> -5071.0657 | AF3: =(MAX(AD3:AD5) - MIN(AD3:AD5))/2 -> 318.55759 | AG3: =AB4-AB3 -> 39557.144 | AH3: =AC4-AC3 -> 39910.166 | AI3: =AVERAGE(AG3:AH4) -> 39940.176 | AJ3: =(MAX(AG3:AH4)-MIN(AG3:AH4))/2 -> 365.8001 | AK3: =AE3/AI3 -> -0.12696653 | AL3: =SQRT((1/AI3)^2*(AF3)^2 + (AE3/(AI3)^2)^2*(AJ3)^2) -> 0.008060192
H4: 242764.56 | I4: 258767.97 | J4: =H4-I4 -> -16003.406 | M4: =H5-H4 -> 125678.31 | N4: =I5-I4 -> 126570.84 | Z4: 277.98267 | AA4: 286.99896 | AB4: =Z4^2 -> 77274.363 | AC4: =AA4^2 -> 82368.404 | AD4: =AB4-AC4 -> -5094.0416 | AG4: =AB5-AB4 -> 40004.651 | AH4: =AC5-AC4 -> 40288.744
H5: 368442.88 | I5: 385338.81 | J5: =H5-I5 -> -16895.938 | Z5: 342.46024 | AA5: 350.22443 | AB5: =Z5^2 -> 117279.01 | AC5: =AA5^2 -> 122657.15 | AD5: =AB5-AC5 -> -5378.1353
B6: 2.94 | C6: =B6*0.03 + 0.1 -> 0.1882 | D6: =11.11 + 65.22*B6 -> 202.8568 | E6: =SQRT(B6^2*'1_TaraturaMagnete'!$D$40^2 + '1_TaraturaMagnete'!$C$40^2*C6^2 +'1_TaraturaMagnete'!$G$40^2 ) -> 12.904954 | F6: =D6/1000 -> 0.2028568 | G6: =E6/1000 -> 0.012904954 | H6: 114495.38 | I6: 134129.55 | J6: =H6-I6 -> -19634.172 | K6: =AVERAGE(J6:J8) -> -21916.974 | L6: =(MAX(J6:J8) - MIN(J6:J8))/2 -> 2397.1797 | M6: =H7-H6 -> 124953.92 | N6: =I7-I6 -> 127007.97 | O6: =AVERAGE(M6:N7) -> 125610.86 | P6: =(MAX(M6:N7)-MIN(M6:N7))/2 -> 1568.6797 | Q6: =K6/O6 -> -0.17448312 | R6: =SQRT((1/O6)^2*(L6)^2 + (K6/(O6)^2)^2*(P6)^2) -> 0.019208172 | T6: =B6 -> 2.94 | U6: =C6 -> 0.1882 | V6: =D6 -> 202.8568 | W6: =E6 -> 12.904954 | X6: =V6/1000 -> 0.2028568 | Y6: =W6/1000 -> 0.012904954 | Z6: 190.90576 | AA6: 206.62711 | AB6: =Z6^2 -> 36445.01 | AC6: =AA6^2 -> 42694.761 | AD6: =AB6-AC6 -> -6249.751 | AE6: =AVERAGE(AD6:AD8) -> -6976.3902 | AF6: =(MAX(AD6:AD8) - MIN(AD6:AD8))/2 -> 763.04707 | AG6: =AB7-AB6 -> 39774.07 | AH6: =AC7-AC6 -> 40427.894 | AI6: =AVERAGE(AG6:AH7) -> 39983.176 | AJ6: =(MAX(AG6:AH7)-MIN(AG6:AH7))/2 -> 499.32934 | AK6: =AE6/AI6 -> -0.17448314 | AL6: =SQRT((1/AI6)^2*(AF6)^2 + (AE6/(AI6)^2)^2*(AJ6)^2) -> 0.019208201
H7: 239449.3 | I7: 261137.52 | J7: =H7-I7 -> -21688.219 | M7: =H8-H7 -> 123870.61 | N7: =I8-I7 -> 126610.92 | Z7: 276.07803 | AA7: 288.31 | AB7: =Z7^2 -> 76219.08 | AC7: =AA7^2 -> 83122.655 | AD7: =AB7-AC7 -> -6903.5746 | AG7: =AB8-AB7 -> 39429.235 | AH7: =AC8-AC7 -> 40301.506
H8: 363319.91 | I8: 387748.44 | J8: =H8-I8 -> -24428.531 | Z8: 340.07105 | AA8: 351.31775 | AB8: =Z8^2 -> 115648.32 | AC8: =AA8^2 -> 123424.16 | AD8: =AB8-AC8 -> -7775.8451
B9: 3.95 | C9: =B9*0.03 + 0.1 -> 0.2185 | D9: =11.11 + 65.22*B9 -> 268.729 | E9: =SQRT(B9^2*'1_TaraturaMagnete'!$D$40^2 + '1_TaraturaMagnete'!$C$40^2*C9^2 +'1_TaraturaMagnete'!$G$40^2 ) -> 15.029574 | F9: =D9/1000 -> 0.268729 | G9: =E9/1000 -> 0.015029574 | H9: 110083.48 | I9: 136630.2 | J9: =H9-I9 -> -26546.719 | K9: =AVERAGE(J9:J11) -> -28814.542 | L9: =(MAX(J9:J11) - MIN(J9:J11))/2 -> 2215.3125 | M9: =H10-H9 -> 125027.33 | N9: =I10-I9 -> 127400.17 | O9: =AVERAGE(M9:N10) -> 126209.4 | P9: =(MAX(M9:N10)-MIN(M9:N10))/2 -> 1186.4219 | Q9: =K9/O9 -> -0.22830742 | R9: =SQRT((1/O9)^2*(L9)^2 + (K9/(O9)^2)^2*(P9)^2) -> 0.017683396 | T9: =B9 -> 3.95 | U9: =C9 -> 0.2185 | V9: =D9 -> 268.729 | W9: =E9 -> 15.029574 | X9: =V9/1000 -> 0.268729 | Y9: =W9/1000 -> 0.015029574 | Z9: 187.19151 | AA9: 208.54434 | AB9: =Z9^2 -> 35040.663 | AC9: =AA9^2 -> 43490.743 | AD9: =AB9-AC9 -> -8450.08 | AE9: =AVERAGE(AD9:AD11) -> -9171.949 | AF9: =(MAX(AD9:AD11) - MIN(AD9:AD11))/2 -> 705.15301 | AG9: =AB10-AB9 -> 39797.432 | AH9: =AC10-AC9 -> 40552.733 | AI9: =AVERAGE(AG9:AH10) -> 40173.7 | AJ9: =(MAX(AG9:AH10)-MIN(AG9:AH10))/2 -> 377.65042 | AK9: =AE9/AI9 -> -0.2283073 | AL9: =SQRT((1/AI9)^2*(AF9)^2 + (AE9/(AI9)^2)^2*(AJ9)^2) -> 0.017683326
H10: 235110.81 | I10: 264030.38 | J10: =H10-I10 -> -28919.562 | M10: =H11-H10 -> 125176.16 | N10: =I11-I10 -> 127233.94 | Z10: 273.56552 | AA10: 289.90253 | AB10: =Z10^2 -> 74838.094 | AC10: =AA10^2 -> 84043.475 | AD10: =AB10-AC10 -> -9205.3809 | AG10: =AB11-AB10 -> 39844.815 | AH10: =AC11-AC10 -> 40499.82
H11: 360286.97 | I11: 391264.31 | J11: =H11-I11 -> -30977.344 | Z11: 338.64865 | AA11: 352.90692 | AB11: =Z11^2 -> 114682.91 | AC11: =AA11^2 -> 124543.29 | AD11: =AB11-AC11 -> -9860.3861
B12: 5.04 | C12: =B12*0.03 + 0.1 -> 0.2512 | D12: =11.11 + 65.22*B12 -> 339.8188 | E12: =SQRT(B12^2*'1_TaraturaMagnete'!$D$40^2 + '1_TaraturaMagnete'!$C$40^2*C12^2 +'1_TaraturaMagnete'!$G$40^2 ) -> 17.348848 | F12: =D12/1000 -> 0.3398188 | G12: =E12/1000 -> 0.017348848 | H12: 111989.84 | I12: 146301.44 | J12: =H12-I12 -> -34311.594 | K12: =AVERAGE(J12:J14) -> -35801.391 | L12: =(MAX(J12:J14) - MIN(J12:J14))/2 -> 2851.5859 | M12: =H13-H12 -> 120032.2 | N12: =I13-I12 -> 119415.31 | O12: =AVERAGE(M12:N13) -> 122928.55 | P12: =(MAX(M12:N13)-MIN(M12:N13))/2 -> 4784.8125 | Q12: =K12/O12 -> -0.29123738 | R12: =SQRT((1/O12)^2*(L12)^2 + (K12/(O12)^2)^2*(P12)^2) -> 0.025818791 | T12: =B12 -> 5.04 | U12: =C12 -> 0.2512 | V12: =D12 -> 339.8188 | W12: =E12 -> 17.348848 | X12: =V12/1000 -> 0.3398188 | Y12: =W12/1000 -> 0.017348848 | Z12: 188.80539 | AA12: 215.79897 | AB12: =Z12^2 -> 35647.475 | AC12: =AA12^2 -> 46569.193 | AD12: =AB12-AC12 -> -10921.718 | AE12: =AVERAGE(AD12:AD14) -> -11395.937 | AF12: =(MAX(AD12:AD14) - MIN(AD12:AD14))/2 -> 907.6879 | AG12: =AB13-AB12 -> 38207.438 | AH12: =AC13-AC12 -> 38011.077 | AI12: =AVERAGE(AG12:AH13) -> 39129.375 | AJ12: =(MAX(AG12:AH13)-MIN(AG12:AH13))/2 -> 1523.0511 | AK12: =AE12/AI12 -> -0.29123738 | AL12: =SQRT((1/AI12)^2*(AF12)^2 + (AE12/(AI12)^2)^2*(AJ12)^2) -> 0.025818782
H13: 232022.05 | I13: 265716.75 | J13: =H13-I13 -> -33694.703 | M13: =H14-H13 -> 123281.77 | N13: =I14-I13 -> 128984.94 | Z13: 271.7626 | AA13: 290.82687 | AB13: =Z13^2 -> 73854.913 | AC13: =AA13^2 -> 84580.271 | AD13: =AB13-AC13 -> -10725.358 | AG13: =AB14-AB13 -> 39241.804 | AH13: =AC14-AC13 -> 41057.18
H14: 355303.81 | I14: 394701.69 | J14: =H14-I14 -> -39397.875 | Z14: 336.29855 | AA14: 354.45373 | AB14: =Z14^2 -> 113096.72 | AC14: =AA14^2 -> 125637.45 | AD14: =AB14-AC14 -> -12540.734
B15: 6.17 | C15: =B15*0.03 + 0.1 -> 0.2851 | D15: =11.11 + 65.22*B15 -> 413.5174 | E15: =SQRT(B15^2*'1_TaraturaMagnete'!$D$40^2 + '1_TaraturaMagnete'!$C$40^2*C15^2 +'1_TaraturaMagnete'!$G$40^2 ) -> 19.772084 | F15: =D15/1000 -> 0.4135174 | G15: =E15/1000 -> 0.019772084 | H15: 104793.11 | I15: 150105.55 | J15: =H15-I15 -> -45312.438 | K15: =AVERAGE(J15:J17) -> -45416.172 | L15: =(MAX(J15:J17) - MIN(J15:J17))/2 -> 1579.8984 | M15: =H16-H15 -> 126859 | N15: =I16-I15 -> 125434.7 | O15: =AVERAGE(M15:N16) -> 124634.48 | P15: =(MAX(M15:N16)-MIN(M15:N16))/2 -> 2658.3984 | Q15: =K15/O15 -> -0.36439493 | R15: =SQRT((1/O15)^2*(L15)^2 + (K15/(O15)^2)^2*(P15)^2) -> 0.014869344 | T15: =B15 -> 6.17 | U15: =C15 -> 0.2851 | V15: =D15 -> 413.5174 | W15: =E15 -> 19.772084 | X15: =V15/1000 -> 0.4135174 | Y15: =W15/1000 -> 0.019772084 | Z15: 182.63812 | AA15: 218.58655 | AB15: =Z15^2 -> 33356.684 | AC15: =AA15^2 -> 47780.079 | AD15: =AB15-AC15 -> -14423.395 | AE15: =AVERAGE(AD15:AD17) -> -14456.416 | AF15: =(MAX(AD15:AD17) - MIN(AD15:AD17))/2 -> 502.89784 | AG15: =AB16-AB15 -> 40380.474 | AH15: =AC16-AC15 -> 39927.108 | AI15: =AVERAGE(AG15:AH16) -> 39672.387 | AJ15: =(MAX(AG15:AH16)-MIN(AG15:AH16))/2 -> 846.19492 | AK15: =AE15/AI15 -> -0.36439491 | AL15: =SQRT((1/AI15)^2*(AF15)^2 + (AE15/(AI15)^2)^2*(AJ15)^2) -> 0.014869357
H16: 231652.11 | I16: 275540.25 | J16: =H16-I16 -> -43888.141 | M16: =H17-H16 -> 121542.2 | N16: =I17-I16 -> 124702 | Z16: 271.54587 | AA16: 296.15399 | AB16: =Z16^2 -> 73737.158 | AC16: =AA16^2 -> 87707.187 | AD16: =AB16-AC16 -> -13970.029 | AG16: =AB17-AB16 -> 38688.085 | AH16: =AC17-AC16 -> 39693.88
H17: 353194.31 | I17: 400242.25 | J17: =H17-I17 -> -47047.938 | Z17: 335.29874 | AA17: 356.93286 | AB17: =Z17^2 -> 112425.24 | AC17: =AA17^2 -> 127401.07 | AD17: =AB17-AC17 -> -14975.824
B18: 7.04 | C18: =B18*0.03 + 0.1 -> 0.3112 | D18: =11.11 + 65.22*B18 -> 470.2588 | E18: =SQRT(B18^2*'1_TaraturaMagnete'!$D$40^2 + '1_TaraturaMagnete'!$C$40^2*C18^2 +'1_TaraturaMagnete'!$G$40^2 ) -> 21.646836 | F18: =D18/1000 -> 0.4702588 | G18: =E18/1000 -> 0.021646836 | H18: 101966.98 | I18: 151646.06 | J18: =H18-I18 -> -49679.078 | K18: =AVERAGE(J18:J20) -> -50688.25 | L18: =(MAX(J18:J20) - MIN(J18:J20))/2 -> 1994.8047 | M18: =H19-H18 -> 124138.53 | N18: =I19-I18 -> 127647.09 | O18: =AVERAGE(M18:N19) -> 127277.39 | P18: =(MAX(M18:N19)-MIN(M18:N19))/2 -> 3259.1172 | Q18: =K18/O18 -> -0.39825024 | R18: =SQRT((1/O18)^2*(L18)^2 + (K18/(O18)^2)^2*(P18)^2) -> 0.018698498 | T18: =B18 -> 7.04 | U18: =C18 -> 0.3112 | V18: =D18 -> 470.2588 | W18: =E18 -> 21.646836 | X18: =V18/1000 -> 0.4702588 | Y18: =W18/1000 -> 0.021646836 | Z18: 180.15854 | AA18: 219.70535 | AB18: =Z18^2 -> 32457.099 | AC18: =AA18^2 -> 48270.442 | AD18: =AB18-AC18 -> -15813.343 | AE18: =AVERAGE(AD18:AD20) -> -16134.573 | AF18: =(MAX(AD18:AD20) - MIN(AD18:AD20))/2 -> 634.96334 | AG18: =AB19-AB18 -> 39514.521 | AH18: =AC19-AC18 -> 40631.329 | AI18: =AVERAGE(AG18:AH19) -> 40513.65 | AJ18: =(MAX(AG18:AH19)-MIN(AG18:AH19))/2 -> 1037.4086 | AK18: =AE18/AI18 -> -0.3982503 | AL18: =SQRT((1/AI18)^2*(AF18)^2 + (AE18/(AI18)^2)^2*(AJ18)^2) -> 0.01869844
H19: 226105.52 | I19: 279293.16 | J19: =H19-I19 -> -53187.641 | M19: =H20-H19 -> 130656.77 | N19: =I20-I19 -> 126667.16 | Z19: 268.27527 | AA19: 298.164 | AB19: =Z19^2 -> 71971.62 | AC19: =AA19^2 -> 88901.771 | AD19: =AB19-AC19 -> -16930.152 | AG19: =AB20-AB19 -> 41589.338 | AH19: =AC20-AC19 -> 40319.411
H20: 356762.28 | I20: 405960.31 | J20: =H20-I20 -> -49198.031 | Z20: 336.98807 | AA20: 359.47348 | AB20: =Z20^2 -> 113560.96 | AC20: =AA20^2 -> 129221.18 | AD20: =AB20-AC20 -> -15660.225
B21: 7.96 | C21: =B21*0.03 + 0.1 -> 0.3388 | D21: =11.11 + 65.22*B21 -> 530.2612 | E21: =SQRT(B21^2*'1_TaraturaMagnete'!$D$40^2 + '1_TaraturaMagnete'!$C$40^2*C21^2 +'1_TaraturaMagnete'!$G$40^2 ) -> 23.635635 | F21: =D21/1000 -> 0.5302612 | G21: =E21/1000 -> 0.023635635 | H21: 99756.094 | I21: 152193.06 | J21: =H21-I21 -> -52436.969 | K21: =AVERAGE(J21:J23) -> -55528.62 | L21: =(MAX(J21:J23) - MIN(J21:J23))/2 -> 3609.5469 | M21: =H22-H21 -> 125760.55 | N21: =I22-I21 -> 127816.41 | O21: =AVERAGE(M21:N22) -> 126701.93 | P21: =(MAX(M21:N22)-MIN(M21:N22))/2 -> 2581.6172 | Q21: =K21/O21 -> -0.43826183 | R21: =SQRT((1/O21)^2*(L21)^2 + (K21/(O21)^2)^2*(P21)^2) -> 0.029855245 | T21: =B21 -> 7.96 | U21: =C21 -> 0.3388 | V21: =D21 -> 530.2612 | W21: =E21 -> 23.635635 | X21: =V21/1000 -> 0.5302612 | Y21: =W21/1000 -> 0.023635635 | Z21: 178.1947 | AA21: 220.10124 | AB21: =Z21^2 -> 31753.352 | AC21: =AA21^2 -> 48444.557 | AD21: =AB21-AC21 -> -16691.205 | AE21: =AVERAGE(AD21:AD23) -> -17675.266 | AF21: =(MAX(AD21:AD23) - MIN(AD21:AD23))/2 -> 1148.891 | AG21: =AB22-AB21 -> 40030.824 | AH21: =AC22-AC21 -> 40685.224 | AI21: =AVERAGE(AG21:AH22) -> 40330.51 | AJ21: =(MAX(AG21:AH22)-MIN(AG21:AH22))/2 -> 821.69069 | AK21: =AE21/AI21 -> -0.43826042 | AL21: =SQRT((1/AI21)^2*(AF21)^2 + (AE21/(AI21)^2)^2*(AJ21)^2) -> 0.029853506
H22: 225516.64 | I22: 280009.47 | J22: =H22-I22 -> -54492.828 | M22: =H23-H22 -> 124033.77 | N22: =I23-I22 -> 129197 | Z22: 267.92569 | AA22: 298.54611 | AB22: =Z22^2 -> 71784.175 | AC22: =AA22^2 -> 89129.781 | AD22: =AB22-AC22 -> -17345.606 | AG22: =AB23-AB22 -> 39481.304 | AH22: =AC23-AC22 -> 41124.686
H23: 349550.41 | I23: 409206.47 | J23: =H23-I23 -> -59656.062 | Z23: 333.56481 | AA23: 360.90784 | AB23: =Z23^2 -> 111265.48 | AC23: =AA23^2 -> 130254.47 | AD23: =AB23-AC23 -> -18988.987
B24: 9 | C24: =B24*0.03 + 0.1 -> 0.37 | D24: =11.11 + 65.22*B24 -> 598.09 | E24: =SQRT(B24^2*'1_TaraturaMagnete'!$D$40^2 + '1_TaraturaMagnete'!$C$40^2*C24^2 +'1_TaraturaMagnete'!$G$40^2 ) -> 25.8898 | F24: =D24/1000 -> 0.59809 | G24: =E24/1000 -> 0.0258898 | H24: 94140.039 | I24: 156457.11 | J24: =H24-I24 -> -62317.07 | K24: =AVERAGE(J24:J26) -> -60407.185 | L24: =(MAX(J24:J26) - MIN(J24:J26))/2 -> 1479.4727 | M24: =H25-H24 -> 128191.23 | N24: =I25-I24 -> 125420.52 | O24: =AVERAGE(M24:N25) -> 126223.01 | P24: =(MAX(M24:N25)-MIN(M24:N25))/2 -> 1385.3555 | Q24: =K24/O24 -> -0.47857506 | R24: =SQRT((1/O24)^2*(L24)^2 + (K24/(O24)^2)^2*(P24)^2) -> 0.012844213 | T24: =B24 -> 9 | U24: =C24 -> 0.37 | V24: =D24 -> 598.09 | W24: =E24 -> 25.8898 | X24: =V24/1000 -> 0.59809 | Y24: =W24/1000 -> 0.0258898 | Z24: 173.10605 | AA24: 223.16327 | AB24: =Z24^2 -> 29965.704 | AC24: =AA24^2 -> 49801.845 | AD24: =AB24-AC24 -> -19836.14 | AE24: =AVERAGE(AD24:AD26) -> -19228.206 | AF24: =(MAX(AD24:AD26) - MIN(AD24:AD26))/2 -> 470.92988 | AG24: =AB25-AB24 -> 40804.535 | AH24: =AC25-AC24 -> 39922.592 | AI24: =AVERAGE(AG24:AH25) -> 40178.034 | AJ24: =(MAX(AG24:AH25)-MIN(AG24:AH25))/2 -> 440.97167 | AK24: =AE24/AI24 -> -0.47857509 | AL24: =SQRT((1/AI24)^2*(AF24)^2 + (AE24/(AI24)^2)^2*(AJ24)^2) -> 0.012844189
H25: 222331.27 | I25: 281877.62 | J25: =H25-I25 -> -59546.359 | M25: =H26-H25 -> 125734.27 | N25: =I26-I25 -> 125546.03 | Z25: 266.02676 | AA25: 299.54037 | AB25: =Z25^2 -> 70770.239 | AC25: =AA25^2 -> 89724.436 | AD25: =AB25-AC25 -> -18954.197 | AG25: =AB26-AB25 -> 40022.463 | AH25: =AC26-AC25 -> 39962.546
H26: 348065.53 | I26: 407423.66 | J26: =H26-I26 -> -59358.125 | Z26: 332.85538 | AA26: 360.12079 | AB26: =Z26^2 -> 110792.7 | AC26: =AA26^2 -> 129686.98 | AD26: =AB26-AC26 -> -18894.281
B30: Dati per analsi dati
B31: B | C31: eB | D31: dD_aree | E31: edD_aree | F31: dD_raggi | G31: edD_raggi
B32: 0.1519852 | C32: 0.011288881 | D32: -0.1269666 | E32: 0.0080603101 | F32: 0.12359434 | G32: 0.0037418989
B33: 0.2028568 | C33: 0.012904954 | D33: -0.17448312 | E33: 0.019208173 | F33: 0.1661095 | G33: 0.0089782117
B34: 0.268729 | C34: 0.015029574 | D34: -0.22830742 | E34: 0.017683396 | F34: 0.22167905 | G34: 0.0093517838
B35: 0.3398188 | C35: 0.017348848 | D35: -0.29123738 | E35: 0.025818791 | F35: 0.2795839 | G35: 0.0062693021
B36: 0.4135174 | C36: 0.019772084 | D36: -0.36439493 | E36: 0.014869344 | F36: 0.35914059 | G36: 0.0019532347
B37: 0.4702588 | C37: 0.021646836 | D37: -0.39825024 | E37: 0.018698498 | F37: 0.40363491 | G37: 0.0034442247
B38: 0.5302612 | C38: 0.023635635 | D38: -0.43826183 | E38: 0.029855246 | F38: 0.42814801 | G38: 0.011189189
B39: 0.59809 | C39: 0.0258898 | D39: -0.47857506 | E39: 0.012844213 | F39: 0.47985743 | G39: 0.0062684528
B59: Cose di Anna qua sotto le ho spostate avevo paura di fare casino
B66: 1° ordine | C66: δ/Δ | D66: i | E66: err i | F66: B | G66: err B | U66: 2° ordine | V66: δ/Δ | W66: i | X66: err i | Y66: B | Z66: err B
C67: 0.11985242 | D67: 2.16 | F67: =11.11 + 65.22*D67 -> 151.9852 | V67: 0.12733626 | W67: 2.16
C68: 0.1571313 | D68: 2.94 | F68: =11.11 + 65.22*D68 -> 202.8568 | V68: 0.17508769 | W68: 2.94
C69: 0.21232733 | D69: 3.95 | F69: =11.11 + 65.22*D69 -> 268.729 | V69: 0.23103092 | W69: 3.95
...
